Workbook

Sheet Rank Report
A1: Google Rank Report – www.cloudlearnerp.com
A2: Search engine: google.com (Google India, English). Report date: 12-Oct-2026. Positions are organic positions (ads, maps & People-Also-Ask boxes excluded).
A4: # | B4: Group | C4: Keyword | D4: City | E4: Google Organic Position | F4: Google Maps (Local Pack) Position | G4: Ranking URL | H4: Status | I4: Data Source | J4: Data Date | K4: Notes
A5: 1 | B5: Kolkata – General | C5: Best SAP Training in Kolkata | D5: Kolkata | E5: Not verified | F5: Not verified | H5: Not verified | I5: Not covered | J5: — | K5: Not in ranking database (low search volume or not in top 100) and no live credits left to check.
A6: 2 | B6: Kolkata – General | C6: SAP Training Kolkata | D6: Kolkata | E6: Not in top 14 | F6: — | H6: Not in top 15 (live) | I6: Live Google SERP (city-level, desktop) | J6: 12-Oct-2026 | K6: Top 3: training.sap.com, emeacademy.co.in, eduwatts.com
A7: 3 | B7: Kolkata – General | C7: SAP Training in KOLKATA | D7: Kolkata | E7: Not in top 15 | F7: — | H7: Not in top 15 (live) | I7: Live Google SERP (city-level, desktop) | J7: 12-Oct-2026 | K7: Top 3: umesl.co.in, theknowledgeacademy.com, sulekha.com
A8: 4 | B8: Kolkata – General | C8: Best ERP training institute in Kolkata | D8: Kolkata | E8: 6 | F8: 2 | G8: https://cloudlearnerp.com/blog/2026/07/26/best-erp-training-institute-in-kolkata-sap-vs-other-erps-a-career-comparison/ | H8: Page 1 (4–10) | I8: Live Google SERP (city-level, desktop) | J8: 12-Oct-2026 | K8: Also #2 in Google Maps local pack (after UN IT ERP Academy)
A9: 5 | B9: Kolkata – General | C9: SAP Training Institute in Kolkata | D9: Kolkata | E9: 9 | F9: n/a | G9: https://www.cloudlearnerp.com/ | H9: Page 1 (4–10) | I9: Google India ranking database (national) | J9: 12–17 Sep 2026
A10: 6 | B10: Kolkata – General | C10: Best SAP Training Institute in Kolkata | D10: Kolkata | E10: Not in top 15 | F10: — | H10: Not in top 15 (live) | I10: Live Google SERP (city-level, desktop) | J10: 12-Oct-2026 | K10: Top 3: community.sap.com, besttrainingkolkata.in, umesl.co.in
A11: 7 | B11: Kolkata – General | C11: SAP Training Academy Kolkata | D11: Kolkata | E11: Not verified | F11: Not verified | H11: Not verified | I11: Not covered | J11: — | K11: Not in ranking database (low search volume or not in top 100) and no live credits left to check.
A12: 8 | B12: Kolkata – General | C12: SAP course in Kolkata | D12: Kolkata | E12: 13 | F12: n/a | G12: https://www.cloudlearnerp.com/ | H12: Page 2 (11–20) | I12: Google India ranking database (national) | J12: 12–17 Sep 2026 | K12: Also 'sap courses in kolkata' = 14
A13: 9 | B13: Kolkata – General | C13: Best institute for SAP course in Kolkata | D13: Kolkata | E13: Not verified | F13: Not verified | H13: Not verified | I13: Not covered | J13: — | K13: Not in ranking database (low search volume or not in top 100) and no live credits left to check.
A14: 10 | B14: Kolkata – General | C14: SAP course in kolkata fees | D14: Kolkata | E14: 10 | F14: — | G14: https://www.cloudlearnerp.com/course/sap-training-in-kolkata | H14: Page 1 (4–10) | I14: Live Google SERP (city-level, desktop) | J14: 12-Oct-2026 | K14: Top 3: icajobguarantee.com, collegedunia.com, emeacademy.co.in
A15: 11 | B15: Kolkata – General | C15: SAP Institute in Kolkata | D15: Kolkata | E15: 11 | F15: n/a | G15: https://www.cloudlearnerp.com/ | H15: Page 2 (11–20) | I15: Google India ranking database (national) | J15: 12–17 Sep 2026
A16: 12 | B16: Mumbai – General | C16: Best SAP Training in Mumbai | D16: Mumbai | E16: Not verified | F16: Not verified | H16: Not verified | I16: Not covered | J16: — | K16: Not in ranking database (low search volume or not in top 100) and no live credits left to check.
A17: 13 | B17: Mumbai – General | C17: SAP Training Mumbai | D17: Mumbai | E17: Not verified | F17: Not verified | H17: Not verified | I17: Not covered | J17: — | K17: Not in ranking database (low search volume or not in top 100) and no live credits left to check.
A18: 14 | B18: Mumbai – General | C18: SAP Training in Mumbai | D18: Mumbai | E18: 9 | F18: — | G18: https://www.cloudlearnerp.com/ | H18: Page 1 (4–10) | I18: Live Google SERP (city-level, desktop) | J18: 12-Oct-2026 | K18: Top 3: training.sap.com, sapeducation.atos.net, aspireit.net
A19: 15 | B19: Mumbai – General | C19: Best ERP training institute in Mumbai | D19: Mumbai | E19: Not verified | F19: Not verified | H19: Not verified | I19: Not covered | J19: — | K19: Not in ranking database (low search volume or not in top 100) and no live credits left to check.
A20: 16 | B20: Mumbai – General | C20: SAP Training Institute in Mumbai | D20: Mumbai | E20: 8 | F20: — | G20: https://www.cloudlearnerp.com/ | H20: Page 1 (4–10) | I20: Live Google SERP (city-level, desktop) | J20: 12-Oct-2026 | K20: National database (Sep) showed 13 for 'sap training institute mumbai'
A21: 17 | B21: Mumbai – General | C21: Best SAP Training Institute in Mumbai | D21: Mumbai | E21: Not in top 16 | F21: — | H21: Not in top 15 (live) | I21: Live Google SERP (city-level, desktop) | J21: 12-Oct-2026 | K21: Top 3: upgradeinfotech.com, mumbai.emeacademy.co.in, justdial.com
A22: 18 | B22: Mumbai – General | C22: SAP Training Academy Mumbai | D22: Mumbai | E22: Not verified | F22: Not verified | H22: Not verified | I22: Not covered | J22: — | K22: Not in ranking database (low search volume or not in top 100) and no live credits left to check.
A23: 19 | B23: Mumbai – General | C23: SAP course in Mumbai | D23: Mumbai | E23: 20 | F23: n/a | G23: https://www.cloudlearnerp.com/ | H23: Page 2 (11–20) | I23: Google India ranking database (national) | J23: 12–17 Sep 2026 | K23: Also 'sap classes in mumbai' = 14 (Mumbai course page)
A24: 20 | B24: Mumbai – General | C24: Best institute for SAP course in Mumbai | D24: Mumbai | E24: Not verified | F24: Not verified | H24: Not verified | I24: Not covered | J24: — | K24: Not in ranking database (low search volume or not in top 100) and no live credits left to check.
A25: 21 | B25: Mumbai – General | C25: SAP course in Mumbai fees | D25: Mumbai | E25: 2 | F25: — | G25: https://www.cloudlearnerp.com/ | H25: Top 3 | I25: Live Google SERP (city-level, desktop) | J25: 12-Oct-2026 | K25: Only training.sap.com ranks above. National database (Sep) showed 11 for 'sap course fees in mumbai' (blog page)
A26: 22 | B26: Mumbai – General | C26: SAP Institute in Mumbai | D26: Mumbai | E26: 18 | F26: n/a | G26: https://www.cloudlearnerp.com/ | H26: Page 2 (11–20) | I26: Google India ranking database (national) | J26: 12–17 Sep 2026
A27: 23 | B27: Pune – General | C27: Best SAP Training in Pune | D27: Pune | E27: Not verified | F27: Not verified | H27: Not verified | I27: Not covered | J27: — | K27: Not in ranking database (low search volume or not in top 100) and no live credits left to check.
A28: 24 | B28: Pune – General | C28: SAP Training Pune | D28: Pune | E28: Not verified | F28: Not verified | H28: Not verified | I28: Not covered | J28: — | K28: Not in ranking database (low search volume or not in top 100) and no live credits left to check.
A29: 25 | B29: Pune – General | C29: SAP Training in Pune | D29: Pune | E29: Not in top 16 | F29: — | H29: Not in top 15 (live) | I29: Live Google SERP (city-level, desktop) | J29: 12-Oct-2026 | K29: Top 3: delphicomputech.com, elearningsolutions.co.in, gtracademy.org
A30: 26 | B30: Pune – General | C30: Best ERP training institute in Pune | D30: Pune | E30: Not verified | F30: Not verified | H30: Not verified | I30: Not covered | J30: — | K30: Not in ranking database (low search volume or not in top 100) and no live credits left to check.
A31: 27 | B31: Pune – General | C31: SAP Training Institute in Pune | D31: Pune | E31: Not in top 14 | F31: — | H31: Not in top 15 (live) | I31: Live Google SERP (city-level, desktop) | J31: 12-Oct-2026 | K31: National database (Sep) showed 10 for 'sap training institute pune' – ranks better outside Pune city
A32: 28 | B32: Pune – General | C32: Best SAP Training Institute in Pune | D32: Pune | E32: Not in top 15 | F32: — | H32: Not in top 15 (live) | I32: Live Google SERP (city-level, desktop) | J32: 12-Oct-2026 | K32: Top 3: training.sap.com, cromacampus.com, training.sap.com
A33: 29 | B33: Pune – General | C33: SAP Training Academy Pune | D33: Pune | E33: Not verified | F33: Not verified | H33: Not verified | I33: Not covered | J33: — | K33: Not in ranking database (low search volume or not in top 100) and no live credits left to check.
A34: 30 | B34: Pune – General | C34: SAP course in Pune | D34: Pune | E34: 26 | F34: n/a | G34: https://www.cloudlearnerp.com/course/sap-training-in-pune | H34: Page 3+ (21–100) | I34: Google India ranking database (national) | J34: 12–17 Sep 2026
A35: 31 | B35: Pune – General | C35: Best institute for SAP course in Pune | D35: Pune | E35: Not verified | F35: Not verified | H35: Not verified | I35: Not covered | J35: — | K35: Not in ranking database (low search volume or not in top 100) and no live credits left to check.
A36: 32 | B36: Pune – General | C36: SAP course in Pune fees | D36: Pune | E36: Not in top 14 | F36: — | H36: Not in top 15 (live) | I36: Live Google SERP (city-level, desktop) | J36: 12-Oct-2026 | K36: National database (Sep) showed 35 for 'sap course fees in pune'
A37: 33 | B37: Pune – General | C37: SAP Institute in Pune | D37: Pune | E37: 11 | F37: n/a | G37: https://www.cloudlearnerp.com/course/sap-training-in-pune | H37: Page 2 (11–20) | I37: Google India ranking database (national) | J37: 12–17 Sep 2026
A38: 34 | B38: Kolkata – SAP Modules | C38: SAP FICO Training Kolkata | D38: Kolkata | E38: Not in top 14 | F38: 1 | G38: https://www.cloudlearnerp.com/ | H38: Not in top 15 (live) | I38: Live Google SERP (city-level, desktop) | J38: 12-Oct-2026 | K38: #1 in Google Maps local pack. Organic top 3: icajobguarantee.com, erpficotrainingkolkata.com, emeacademy.co.in
A39: 35 | B39: Kolkata – SAP Modules | C39: SAP MM Training Kolkata | D39: Kolkata | E39: Not verified | F39: Not verified | H39: Not verified | I39: Not covered | J39: — | K39: Not in ranking database (low search volume or not in top 100) and no live credits left to check. Related: 'sap mm course in pune' = 18 nationally.
A40: 36 | B40: Kolkata – SAP Modules | C40: SAP SD Training Kolkata | D40: Kolkata | E40: Not verified | F40: Not verified | H40: Not verified | I40: Not covered | J40: — | K40: Not in ranking database (low search volume or not in top 100) and no live credits left to check.
A41: 37 | B41: Kolkata – SAP Modules | C41: SAP ABAP Training Kolkata | D41: Kolkata | E41: Not verified | F41: Not verified | H41: Not verified | I41: Not covered | J41: — | K41: Not in ranking database (low search volume or not in top 100) and no live credits left to check. Related: generic 'sap abap development for hana' = 42 nationally.
...

Sheet Summary
A1: Summary by keyword group
A3: Group | B3: Total keywords | C3: Top 3 | D3: Page 1 (4–10) | E3: Page 2 (11–20) | F3: Page 3+ (21–100) | G3: Not in top 15 (live) | H3: Not verified
A4: Kolkata – General | B4: =COUNTIF('Rank Report'!$B$5:$B$85,A4) -> 11 | C4: =COUNTIFS('Rank Report'!$B$5:$B$85,$A4,'Rank Report'!$H$5:$H$85,"Top 3") -> 0 | D4: =COUNTIFS('Rank Report'!$B$5:$B$85,$A4,'Rank Report'!$H$5:$H$85,"Page 1 (4–10)") -> 3 | E4: =COUNTIFS('Rank Report'!$B$5:$B$85,$A4,'Rank Report'!$H$5:$H$85,"Page 2 (11–20)") -> 2 | F4: =COUNTIFS('Rank Report'!$B$5:$B$85,$A4,'Rank Report'!$H$5:$H$85,"Page 3+ (21–100)") -> 0 | G4: =COUNTIFS('Rank Report'!$B$5:$B$85,$A4,'Rank Report'!$H$5:$H$85,"Not in top 15 (live)") -> 3 | H4: =COUNTIFS('Rank Report'!$B$5:$B$85,$A4,'Rank Report'!$H$5:$H$85,"Not verified") -> 3
A5: Mumbai – General | B5: =COUNTIF('Rank Report'!$B$5:$B$85,A5) -> 11 | C5: =COUNTIFS('Rank Report'!$B$5:$B$85,$A5,'Rank Report'!$H$5:$H$85,"Top 3") -> 1 | D5: =COUNTIFS('Rank Report'!$B$5:$B$85,$A5,'Rank Report'!$H$5:$H$85,"Page 1 (4–10)") -> 2 | E5: =COUNTIFS('Rank Report'!$B$5:$B$85,$A5,'Rank Report'!$H$5:$H$85,"Page 2 (11–20)") -> 2 | F5: =COUNTIFS('Rank Report'!$B$5:$B$85,$A5,'Rank Report'!$H$5:$H$85,"Page 3+ (21–100)") -> 0 | G5: =COUNTIFS('Rank Report'!$B$5:$B$85,$A5,'Rank Report'!$H$5:$H$85,"Not in top 15 (live)") -> 1 | H5: =COUNTIFS('Rank Report'!$B$5:$B$85,$A5,'Rank Report'!$H$5:$H$85,"Not verified") -> 5
A6: Pune – General | B6: =COUNTIF('Rank Report'!$B$5:$B$85,A6) -> 11 | C6: =COUNTIFS('Rank Report'!$B$5:$B$85,$A6,'Rank Report'!$H$5:$H$85,"Top 3") -> 0 | D6: =COUNTIFS('Rank Report'!$B$5:$B$85,$A6,'Rank Report'!$H$5:$H$85,"Page 1 (4–10)") -> 0 | E6: =COUNTIFS('Rank Report'!$B$5:$B$85,$A6,'Rank Report'!$H$5:$H$85,"Page 2 (11–20)") -> 1 | F6: =COUNTIFS('Rank Report'!$B$5:$B$85,$A6,'Rank Report'!$H$5:$H$85,"Page 3+ (21–100)") -> 1 | G6: =COUNTIFS('Rank Report'!$B$5:$B$85,$A6,'Rank Report'!$H$5:$H$85,"Not in top 15 (live)") -> 4 | H6: =COUNTIFS('Rank Report'!$B$5:$B$85,$A6,'Rank Report'!$H$5:$H$85,"Not verified") -> 5
A7: Kolkata – SAP Modules | B7: =COUNTIF('Rank Report'!$B$5:$B$85,A7) -> 16 | C7: =COUNTIFS('Rank Report'!$B$5:$B$85,$A7,'Rank Report'!$H$5:$H$85,"Top 3") -> 0 | D7: =COUNTIFS('Rank Report'!$B$5:$B$85,$A7,'Rank Report'!$H$5:$H$85,"Page 1 (4–10)") -> 0 | E7: =COUNTIFS('Rank Report'!$B$5:$B$85,$A7,'Rank Report'!$H$5:$H$85,"Page 2 (11–20)") -> 0 | F7: =COUNTIFS('Rank Report'!$B$5:$B$85,$A7,'Rank Report'!$H$5:$H$85,"Page 3+ (21–100)") -> 0 | G7: =COUNTIFS('Rank Report'!$B$5:$B$85,$A7,'Rank Report'!$H$5:$H$85,"Not in top 15 (live)") -> 1 | H7: =COUNTIFS('Rank Report'!$B$5:$B$85,$A7,'Rank Report'!$H$5:$H$85,"Not verified") -> 15
A8: Mumbai – SAP Modules | B8: =COUNTIF('Rank Report'!$B$5:$B$85,A8) -> 16 | C8: =COUNTIFS('Rank Report'!$B$5:$B$85,$A8,'Rank Report'!$H$5:$H$85,"Top 3") -> 0 | D8: =COUNTIFS('Rank Report'!$B$5:$B$85,$A8,'Rank Report'!$H$5:$H$85,"Page 1 (4–10)") -> 0 | E8: =COUNTIFS('Rank Report'!$B$5:$B$85,$A8,'Rank Report'!$H$5:$H$85,"Page 2 (11–20)") -> 1 | F8: =COUNTIFS('Rank Report'!$B$5:$B$85,$A8,'Rank Report'!$H$5:$H$85,"Page 3+ (21–100)") -> 0 | G8: =COUNTIFS('Rank Report'!$B$5:$B$85,$A8,'Rank Report'!$H$5:$H$85,"Not in top 15 (live)") -> 0 | H8: =COUNTIFS('Rank Report'!$B$5:$B$85,$A8,'Rank Report'!$H$5:$H$85,"Not verified") -> 15
A9: Pune – SAP Modules | B9: =COUNTIF('Rank Report'!$B$5:$B$85,A9) -> 16 | C9: =COUNTIFS('Rank Report'!$B$5:$B$85,$A9,'Rank Report'!$H$5:$H$85,"Top 3") -> 1 | D9: =COUNTIFS('Rank Report'!$B$5:$B$85,$A9,'Rank Report'!$H$5:$H$85,"Page 1 (4–10)") -> 0 | E9: =COUNTIFS('Rank Report'!$B$5:$B$85,$A9,'Rank Report'!$H$5:$H$85,"Page 2 (11–20)") -> 0 | F9: =COUNTIFS('Rank Report'!$B$5:$B$85,$A9,'Rank Report'!$H$5:$H$85,"Page 3+ (21–100)") -> 0 | G9: =COUNTIFS('Rank Report'!$B$5:$B$85,$A9,'Rank Report'!$H$5:$H$85,"Not in top 15 (live)") -> 1 | H9: =COUNTIFS('Rank Report'!$B$5:$B$85,$A9,'Rank Report'!$H$5:$H$85,"Not verified") -> 14
A10: TOTAL | B10: =SUM(B4:B9) -> 81 | C10: =SUM(C4:C9) -> 2 | D10: =SUM(D4:D9) -> 5 | E10: =SUM(E4:E9) -> 6 | F10: =SUM(F4:F9) -> 1 | G10: =SUM(G4:G9) -> 10 | H10: =SUM(H4:H9) -> 57
A12: Key highlights
A13: • Best positions: 'SAP course in Mumbai fees' #2 (Mumbai), 'SAP MM Training Pune' #3 (Pune), 'SAP Training Institute in Mumbai' #8, 'SAP Training in Mumbai' #9, 'SAP Training Institute in Kolkata' #9.
A14: • Google Maps: CloudLearn ERP is #1 in the local pack for 'SAP FICO Training Kolkata' and #2 for 'Best ERP training institute in Kolkata'.
A15: • Gaps: not in top ~15 in Kolkata for 'SAP Training Kolkata', 'SAP Training in Kolkata', 'Best SAP Training Institute in Kolkata'; and in Pune for 'SAP Training in Pune', 'SAP Training Institute in Pune', 'Best SAP Training Institute in Pune', 'SAP course in Pune fees', 'SAP FICO Training Pune'.
A16: • Most module + city keywords (e.g. 'SAP SD Training Kolkata') are too low-volume to appear in the ranking database and could not be live-checked (credits exhausted) – see Methodology.

Sheet Methodology
A1: How this report was produced
A3: 1. Live Google SERP (17 keywords): fetched 12-Oct-2026 from google.com for India (gl=IN, hl=en), desktop, localised to the keyword's city (Kolkata / Mumbai / Pune) via OpenSEO (DataForSEO). Top 20 SERP rows were captured, which equals roughly the top 13–16 organic results. 'Not in top N' means the site was not found within the organic results captured.
A4: 2. Google India ranking database (national): 7 keywords were taken from OpenSEO's ranked-keywords index for cloudlearnerp.com (Google India, national, refreshed 12–17 Sep 2026). These positions are national, not city-localised, and can differ from what a searcher in that city sees.
A5: 3. Not verified: the remaining keywords are not in the ranking database (usually because their monthly search volume is too low to be tracked, or the site is outside the top 100). The OpenSEO credit balance ran out after 17 live checks, and Semrush returned 'not enough API units', so these were not checked. Adding credits would allow a live check of all 91 keywords (~5 credits per keyword at top-20 depth, ~25 at top-100 depth).
A7: Notes
A8: • 'Organic position' excludes ads, the Google Maps local pack, People-Also-Ask, AI Overview and video boxes. The 'Local Pack' column shows the position inside the Google Maps 3-pack, where it was checked.
A9: • Rankings change daily and vary by exact location, device and personalisation.
A10: • Keywords 'SAP EWS Training …' may be a typo of 'SAP EHS', and 'SAP Flori Training Mumbai' a typo of 'Fiori'. They were kept as supplied.
